<?xml version="1.0"?>
<robot xmlns="http://drake.mit.edu"
 xmlns:xsi="http://www.w3.org/2001/XMLSchema-instance"
 xsi:schemaLocation="http://drake.mit.edu ../../../doc/drakeURDF.xsd" name="Cylinder">

      <link name="base_root">
    <inertial>
      <origin xyz="0 0 0" rpy="0 0 0"/>
      <mass value="0.01"/>
      <inertia ixx="0" ixy="0" ixz="0" iyy="0" iyz="0" izz="0" />
    </inertial>
    <visual>
      <origin xyz="0 0 0" />
      <geometry>
        <sphere radius=".015" />
      </geometry> 
      <material name="green" />
    </visual>
  </link>
      
    <link name="base_wheel">
    <inertial>
      <origin xyz="0 0 0" rpy="0 0 0"/>
      <mass value="0.01"/>
      <inertia ixx="0" ixy="0" ixz="0" iyy="0" iyz="0" izz="0" />
    </inertial>
    <visual name="base_wheel_vis">
      <origin xyz="0 0 0" />
      <geometry>
        <sphere radius=".015" />
      </geometry> 
      <material name="green" />
    </visual>
  </link>
    
<!--        <link name="base_arm">
    <inertial>
      <origin xyz="0 0 0" rpy="0 0 0"/>
      <mass value="0.01"/>
      <inertia ixx="0" ixy="0" ixz="0" iyy="0" iyz="0" izz="0" />
    </inertial>
    <visual>
      <origin xyz="0 0 0" />
      <geometry>
        <sphere radius=".015" />
      </geometry> 
      <material name="green" />
    </visual>
  </link>-->
  
  <link name="wheel">
     <origin xyz="0 0 0" rpy="0 0 0" />
    <visual>
     <origin xyz="0 0 0" rpy="1.57 0 0" />
      <geometry>
        <cylinder radius="0.3" length="1.0"/>
      </geometry>
    </visual>
    <collision>
      <geometry>
        <cylinder radius="0.3" length="1.0"/>
      </geometry>
      <origin xyz="0 0 0" rpy="1.57 0 0" />
    </collision>
    <inertial>
      <mass value="10"/>
      <inertia ixx="0.833" ixy="0.0" ixz="0.0" iyy="0.45" iyz="0.0" izz="0.833"/>
      <origin xyz="0 0 0" rpy="0 0 0" />
    </inertial>
  </link>
  
<!--  *****2-Link ARM****-->
  
<!--    <link name="arm1">
    <inertial> 
      <origin xyz="0 0 0" rpy="1.57 0 0" />
      <mass value="10" />
      <inertia ixx="3.334" ixy="0" ixz="0" iyy="0.0125" iyz="0" izz="3.334"/> 
    </inertial>
    <visual>
      <origin xyz="0 0 1" rpy="0 0 0" />
      <geometry>
         <cylinder length="2" radius=".05" />
      </geometry>
    <material name="blue">
       <color rgba="1 0 .8 1"/>
      </material>
    </visual> 
    <collision>
      <origin xyz="0 0 1" rpy="0 0 0" />
      <geometry>
         <cylinder length="2" radius=".05" />
      </geometry>
    </collision>
  </link>
    
   <link name="arm2">
    <inertial> 
      <origin xyz="0 0 0" rpy="1.57 0 0" />
      <mass value="10" />
      <inertia ixx="3.334" ixy="0" ixz="0" iyy="0.0125" iyz="0" izz="3.334"/> 
    </inertial>
    <visual>
      <origin xyz="0 0 0" rpy="0 0 0" />
      <geometry>
         <cylinder length="1" radius=".05" />
      </geometry>
    </visual> 10
    <collision>
      <origin xyz="0 0 0" rpy="0 0 0" />
      <geometry>
         <cylinder length="2" radius=".05" />
      </geometry>
    </collision>
  </link>-->
    
  <joint name="root" type="fixed">
    <parent link="base_root"/>
    <child link="base_wheel" />
    <origin xyz="0 0 0" rpy="0 0 0"/>
  </joint>
    
  <joint name="theta" type="continuous">
    <parent link="base_wheel"/>
    <child link="wheel" />
    <axis xyz="0 1 0" />
    <dynamics damping="0.1" />
  </joint>
<!--    <joint name="arm_root" type="fixed">
    <parent link="base_arm"/>
    <child link="wheel" />
    <axis xyz="0 1 0" />
    <dynamics damping="0.1" />
  </joint>-->
    
<!--    <joint name="arm_angle_1" type="continuous">
    <parent link="wheel" />
    <child link="arm1" />
    <axis xyz="0 1 0" />
  </joint>
    
  <joint name="arm_angle_2" type="continuous">
    <parent link="arm1" />
    <child link="arm2" />
    <axis xyz="0 1 0" />
  <origin xyz="0 0 2" rpy="0 0 0"/>
  </joint>-->
  
    <transmission type="SimpleTransmission" name="drive">
    <actuator name="tau_d" />
    <joint name="theta" />
    <mechanicalReduction>1</mechanicalReduction>
  </transmission>
    
<!--    <transmission type="SimpleTransmission" name="arm_angle_control">
    <actuator name="tau_a" />
    <joint name="arm_angle" />
    <mechanicalReduction>1</mechanicalReduction>
  </transmission>
  -->
</robot>
