<?xml version="1.0"?>
<robot xmlns="http://drake.mit.edu"
 xmlns:xsi="http://www.w3.org/2001/XMLSchema-instance"
 xsi:schemaLocation="http://drake.mit.edu ../../../doc/drakeURDF.xsd" name="Cylinder">

<!--      <link name="base_root">
    <inertial>
      <origin xyz="0 0 0" rpy="0 0 0"/>
      <mass value="0.01"/>
      <inertia ixx="0" ixy="0" ixz="0" iyy="0" iyz="0" izz="0" />
    </inertial>
    <visual>
      <origin xyz="0 0 0" />
      <geometry>
        <sphere radius=".015" />
      </geometry> 
      <material name="green" />
    </visual>
  </link>-->
      
    <link name="base_wheel">
    <inertial>
      <origin xyz="0 0 0" rpy="0 0 0"/>
      <mass value="0.0001"/>
      <inertia ixx="0" ixy="0" ixz="0" iyy="0" iyz="0" izz="0" />
    </inertial>
    <visual>
      <origin xyz="0 0 0" />
      <geometry>
        <sphere radius=".015" />
      </geometry> 
      <material name="green" />
    </visual>
  </link>
    
        <link name="base_arm">
    <inertial>
      <origin xyz="0 0 0" rpy="0 0 0"/>
      <mass value="0.0001"/>
      <inertia ixx="0" ixy="0" ixz="0" iyy="0" iyz="0" izz="0" />
    </inertial>
    <visual>
      <origin xyz="0 0 0" />
      <geometry>
        <sphere radius=".015" />
      </geometry> 
      <material name="green" />
    </visual>
  </link>
  
  <link name="wheel">
     <origin xyz="0 0 0" rpy="0 0 0" />
    <visual>
     <origin xyz="0 0 0" rpy="1.57 0 0" />
      <geometry>
        <cylinder radius="0.5" length="1.0"/>
      </geometry>
    </visual>
    <collision>
      <geometry>
        <cylinder radius="0.5" length="1.0"/>
      </geometry>
      <origin xyz="0 0 0" rpy="1.57 0 0" />
    </collision>
    <inertial>
      <mass value="10"/>
      <inertia ixx="0.833" ixy="0.0" ixz="0.0" iyy="0.45" iyz="0.0" izz="0.833"/>
      <origin xyz="0 0 0" rpy="0 0 0" />
    </inertial>
  </link>
  
    <link name="marker">
     <origin xyz="0 0 0" rpy="0 0 0" />
    <visual>
     <origin xyz="0 0 0" rpy="0 0 0" />
      <geometry>
        <box size="0.1 0.1 0.3"/>
      </geometry>
      <material name="cyan" />
      <color rgba="0 0.9 0.9 1.0"/>
    </visual>
    <inertial>
      <mass value="0.1"/>
      <inertia ixx="0.0" ixy="0.0" ixz="0.0" iyy="0.0" iyz="0.0" izz="0.0"/>
      <origin xyz="0 0 0" rpy="0 0 0" />
    </inertial>
  </link>
   <link name="arm1">
    <inertial> 
      <origin xyz="0 0 0.5" rpy="0 0 0" />
      <mass value="10" />
      <inertia ixx="0.84" ixy="0" ixz="0" iyy="0.84" iyz="0" izz="0.0167"/> 
    </inertial>
    <visual>
      <origin xyz="0 0 0.5" rpy="0 1.57 0" />
      <geometry>
          <box size="1 0.1 0.1" />
         <!--<cylinder length="1" radius=".05" />-->
      </geometry>
    <material name="blue">
       <color rgba="1 0 .8 1"/>
      </material>
    </visual> 

  </link>
    
   <link name="arm2">
    <inertial> 
      <origin xyz="0 0 0" rpy="0 0 0" />
      <mass value="10" />
      <inertia ixx="0.84" ixy="0" ixz="0" iyy="0.84" iyz="0" izz="0.0167"/> 
    </inertial>
    <visual>
      <origin xyz="0 0 0" rpy="0 1.57 0" />
      <geometry>
         <box size="1 0.1 0.1" />
      </geometry>
    </visual> 
    <!--<collision>
      <origin xyz="0 0 0" rpy="0 0 0" />
      <geometry>
         <cylinder length="2" radius=".05" />
      </geometry>
    </collision>-->
    <collision group="arm">
      <origin rpy="0 0 0" xyz="0 0 0.5"/>
      <geometry>
        <sphere radius="1e-6"/>
      </geometry>
    </collision>
    <visual>
      <origin rpy="0 0 0" xyz="0 0 0.5"/>
      <geometry>
        <sphere radius="0.01"/>
      </geometry>
    </visual>
  </link>
   
       
    
<!--  <joint name="root" type="fixed">
    <parent link="base_root"/>
    <child link="base_wheel" />
    <origin xyz="0 0 0.3" rpy="0 0 0"/>
  </joint>-->
  
    <joint name="marker" type="fixed">
    <parent link="wheel"/>
    <child link="marker" />
    <origin xyz="0 0.6 0.2" rpy="0 0 0"/>
  </joint>
    
  <joint name="theta" type="continuous">
    <parent link="base_wheel"/>
    <child link="wheel" />
    <axis xyz="0 1 0" />
    <dynamics damping="0.1" />
  </joint>
    <joint name="arm_root" type="fixed">
    <parent link="base_wheel"/>
    <child link="base_arm" />
    <axis xyz="0 1 0" />
    <dynamics damping="0.1" />
  </joint>
    
   <joint name="arm_angle_1" type="revolute">
    <parent link="base_arm" />
    <child link="arm1" />
    <axis xyz="0 1 0" />
    <origin xyz="0 0 0" rpy="0 0 0"/>
     <dynamics damping="0.1" />
  </joint>
    
  <joint name="arm_angle_2" type="revolute">
    <parent link="arm1" />
    <child link="arm2" />
    <axis xyz="0 1 0" />
  <origin xyz="0 0 1" rpy="0 0 0"/>
     <dynamics damping="0.1" />
  </joint>-
  
    <transmission type="SimpleTransmission" name="drive">
    <actuator name="tau_d" />
    <joint name="theta" />
    <mechanicalReduction>1</mechanicalReduction>
  </transmission>
    
    <transmission type="SimpleTransmission" name="arm_angle_control_1">
    <actuator name="tau_a" />
    <joint name="arm_angle_1" />
    <mechanicalReduction>1</mechanicalReduction>
  </transmission>
<transmission type="SimpleTransmission" name="arm_angle_control_2">
    <actuator name="tau_b" />
    <joint name="arm_angle_2" />
    <mechanicalReduction>1</mechanicalReduction>
  </transmission>
  
</robot>
