<?xml version="1.0"?>
<robot xmlns="http://drake.mit.edu"
 xmlns:xsi="http://www.w3.org/2001/XMLSchema-instance"
 xsi:schemaLocation="http://drake.mit.edu ../../../doc/drakeURDF.xsd" name="ballbot">


 <link name="base_wheel">
 <visual>
   <origin xyz="0 0 0" />
   <geometry>
     <sphere radius=".5" />
   </geometry>
   <material name="Gold">
	    <color rgba="1.0 0.67 0 1.0"/>
    </material>
 </visual>
 <inertial>
   <mass value="10"/>
   <inertia ixx="1" ixy="0.0" ixz="0.0" iyy="1" iyz="0.0" izz="1"/>
   <origin xyz="0 0 0" rpy="0 0 0" />
 </inertial>
</link>

  <link name="ball">
    <visual>
      <geometry>
        <sphere radius="0.5"/>
      </geometry>
      <origin xyz="0 0 0"/>
      <material name="Gold">
         <color rgba="1.0 0.67 0 1.0"/>
       </material>
    </visual>
    <visual>
      <geometry>
        <sphere radius="0.1"/>
      </geometry>
      <origin xyz=".5 0 0"/>
    </visual>
    <visual>
      <geometry>
        <sphere radius="0.1"/>
      </geometry>
      <origin xyz="-0.5 0 0"/>
    </visual>
    <collision>
      <geometry>
        <sphere radius="0.5"/>
      </geometry>
      <origin xyz="0 0 0"/>
    </collision>
    <inertial>
      <mass value="10"/>
      <inertia ixx="1" ixy="0.0" ixz="0.0" iyy="1" iyz="0.0" izz="1"/>
      <origin xyz="0 0 0"/>
    </inertial>
  </link>

<!-- <link name="arm1">
  <inertial>
    <origin xyz="0 0 0.5" rpy="0 0 0" />
    <mass value="10" />
    <inertia ixx="0.83958" ixy="0" ixz="0" iyy="0.83958" iyz="0" izz="0.0125"/>
  </inertial>
  <visual>
    <origin xyz="0 0 0.5" rpy="0 0 0" />
    <geometry>
       <cylinder length="1" radius=".05" />
    </geometry>
  <material name="blue">
     <color rgba="1 0 .8 1"/>
    </material>
  </visual>
  <collision>
    <origin xyz="0 0 0.5" rpy="0 0 0" />
    <geometry>
       <cylinder length="1" radius=".05" />
    </geometry>
  </collision>
</link> -->

<joint name="theta" type="revolute">
  <parent link="base_wheel"/>
  <child link="ball" />
  <axis xyz="0 1 0" />
  <limit effort="300" lower="-1.91986218" upper="1.91986218" velocity="20"/>
  <dynamics damping="0.1" />
</joint>

<!-- <joint name="arm_angle_1" type="continuous">
<parent link="base_wheel" />
<child link="arm1" />
<origin xyz="0 0 0.5" rpy="0 0 0" />
<axis xyz="0 1 0" />
<dynamics damping="0.1" />
</joint> -->

<transmission type="SimpleTransmission" name="drive">
<actuator name="tau_d" />
<joint name="theta" />
<mechanicalReduction>1</mechanicalReduction>
</transmission>


</robot>
