<?xml version="1.0"?>
<robot xmlns="http://drake.mit.edu"
 xmlns:xsi="http://www.w3.org/2001/XMLSchema-instance"
 xsi:schemaLocation="http://drake.mit.edu ../../../doc/drakeURDF.xsd" name="TWIP">

      <link name="base_root">
    <inertial>
      <origin xyz="0 0 0" rpy="0 0 0"/>
      <mass value="0.1"/>
      <inertia ixx="0.0004" ixy="0" ixz="0" iyy="0.0004" iyz="0" izz="0.0004" />
    </inertial>
    <visual>
      <origin xyz="0 0 0" />
      <geometry>
        <sphere radius=".1" />
      </geometry>
      <material name="green" />
    </visual>
  </link>

    <!-- <link name="base_wheel">
    <inertial>
      <origin xyz="0 0 0" rpy="0 0 0"/>
      <mass value="0.01"/>
      <inertia ixx="0" ixy="0" ixz="0" iyy="0" iyz="0" izz="0" />
    </inertial>
    <visual>
      <origin xyz="0 0 0" />
      <geometry>
        <sphere radius=".015" />
      </geometry>
      <material name="green" />
    </visual>
  </link> -->

<!--        <link name="base_arm">
    <inertial>
      <origin xyz="0 0 0" rpy="0 0 0"/>
      <mass value="0.01"/>
      <inertia ixx="0" ixy="0" ixz="0" iyy="0" iyz="0" izz="0" />
    </inertial>
    <visual>
      <origin xyz="0 0 0" />
      <geometry>
        <sphere radius=".015" />
      </geometry>
      <material name="green" />
    </visual>
  </link>-->

  <link name="wheel">
     <origin xyz="0 0 0" rpy="0 0 0" />
    <visual>
     <origin xyz="0 0 -0.5" rpy="0 0 0" />
      <geometry>
        <cylinder radius="0.1" length="1.0"/>
      </geometry>
      <material name="white">
         <color rgba="0.46 0.53 0.6 0"/>
    </material>
    </visual>
    <collision group="center">
      <origin rpy="0 0 0" xyz="0 0 -1"/>
      <geometry>
        <sphere radius="0.0"/>
      </geometry>
    </collision>
    <collision group="edge">
      <origin rpy="0 0 0" xyz="0.05 0 -1"/>
      <geometry>
        <sphere radius="0.0"/>
      </geometry>
    </collision>
    <visual group="center">
      <origin rpy="0 0 0" xyz="0 0 -1"/>
      <geometry>
        <sphere radius="0.05"/>
      </geometry>
    </visual>
    <visual group="edge">
      <origin rpy="0 0 0" xyz="0.05 0 -1"/>
      <geometry>
        <sphere radius="0.05"/>
      </geometry>
    </visual>
    <inertial>
      <mass value="1"/>
      <inertia ixx="0.0858" ixy="0.0" ixz="0.0" iyy="0.0858" iyz="0.0" izz="0.005"/>
      <origin xyz="0 0 -0.5" rpy="0 0 0" />
    </inertial>
  </link>


    <link name="arm1">
    <inertial>
      <origin xyz="0 0 0.5" rpy="0 0 0" />
      <mass value="1" />
      <inertia ixx="0.085833" ixy="0" ixz="0" iyy="0.085833" iyz="0" izz="0.005"/>
    </inertial>
    <visual>
      <origin xyz="0 0 0.5" rpy="0 0 0" />
      <geometry>
         <cylinder length="1" radius=".1" />
      </geometry>
    <material name="grey">
       <color rgba="0.5 0.5 .5 1"/>
      </material>
    </visual>
    <visual group="joint2">
      <origin xyz="0 0 1" />
      <geometry>
        <sphere radius=".1" />
      </geometry>
    </visual>
    <!-- <collision>
      <origin xyz="0 0 0.5" rpy="0 0 0" />
      <geometry>
         <cylinder length="1" radius=".1" />
      </geometry>
    </collision> -->
  </link>

   <link name="arm2">
    <inertial>
      <origin xyz="0 0 0.5" rpy="0 0 0" />
      <mass value="1" />
      <inertia ixx="0.4292" ixy="0" ixz="0" iyy="0.4292" iyz="0" izz="0.0250"/>
    </inertial>
    <visual>
      <origin xyz="0 0 0.5" rpy="0 0 0" />
      <geometry>
         <cylinder length="1" radius=".1" />
      </geometry>
      <material name="Darkorange">
           <color rgba="1 0.549 0 1"/>
        </material>
    </visual>
    <!-- <collision>
      <origin xyz="0 0 0.5" rpy="0 0 0" />
      <geometry>
         <cylinder length="1" radius=".1" />
      </geometry>
      <surface>
          <friction>
            <ode>
              <mu>0</mu>
              <mu2>0</mu2>
            </ode>
          </friction>
        </surface>
    </collision> -->
  </link>

  <!-- <joint name="root" type="fixed">
    <parent link="base_root"/>
    <child link="base_wheel" />
    <origin xyz="0 0 0.3" rpy="0 0 0"/>
  </joint> -->

  <joint name="theta" type="revolute">
    <parent link="base_root"/>
    <child link="wheel" />
    <axis xyz="0 1 0" />
    <dynamics damping="0.1" />
    <limit effort="inf" lower="-inf" upper="inf" velocity="inf"/>
  </joint>
<!--    <joint name="arm_root" type="fixed">
    <parent link="base_arm"/>
    <child link="wheel" />
    <axis xyz="0 1 0" />
    <dynamics damping="0.1" />
  </joint>-->

    <joint name="arm_angle_1" type="revolute">
    <!-- <origin xyz="0 0 -1" rpy="0 0 0"/> -->
    <parent link="base_root" />
    <child link="arm1" />
    <axis xyz="0 1 0" />
    <limit effort="inf" lower="-inf" upper="inf" velocity="inf"/>
  </joint>

  <joint name="arm_angle_2" type="revolute">
    <parent link="arm1" />
    <child link="arm2" />
    <axis xyz="0 1 0" />
  <origin xyz="0 0 1" rpy="0 0 0"/>
  <limit effort="inf" lower="-inf" upper="inf" velocity="inf"/>
  </joint>

    <transmission type="pr2_mechanism_model/SimpleTransmission" name="drive">
    <actuator name="tau_d" />
    <joint name="theta" />
    <mechanicalReduction>1</mechanicalReduction>
  </transmission>

    <transmission type="pr2_mechanism_model/SimpleTransmission" name="arm1_angle_control">
    <actuator name="tau_a1" />
    <joint name="arm_angle_1" />
    <mechanicalReduction>1</mechanicalReduction>
  </transmission>

   <transmission type="pr2_mechanism_model/SimpleTransmission" name="arm2_angle_control">
    <actuator name="tau_a2" />
    <joint name="arm_angle_2" />
    <mechanicalReduction>1</mechanicalReduction>
  </transmission>

</robot>
